Workbook

Sheet Dashboard
A1: CONTROLE FINANCEIRO — WILL & SÁ | N1: Receitas | O1: Despesas
A2: Mês: | B2: 7 | C2: {=INDEX(Config!$J$2:$J$13,B2)} | D2: {=UPPER(INDEX(Config!$J$2:$J$13,B2))&" "&B3} | M2: Ciclo 1 | N2: 1190 | O2: 0
A3: Ano: | B3: 2026 | D3: =IF(B5>0,"Renda: R$ "&TEXT(B5,"#.#0")&" | Gasto: R$ "&TEXT(G5,"#.#0")&" | Sobra: "&TEXT(IFERROR(K5/B5,0),"0%"),"Nenhum lançamento neste mês") | H3: Visualizar: | I3: C1+C2 | M3: Ciclo 2 | N3: 0 | O3: 0
A5: 📥 RECEITAS | B5: =IFERROR(IF($I$3="C1",B11,IF($I$3="C2",C11,IF($I$3="Anual",SUMPRODUCT((Lancamentos!$A$2:$A$487="Receita")*(Lancamentos!$B$2:$B$487<>"")*(YEAR(Lancamentos!$B$2:$B$487)=$B$3)*Lancamentos!$G$2:$G$487),D11))),0) | F5: 📤 DESPESAS | G5: =IFERROR(IF($I$3="C1",B12,IF($I$3="C2",C12,IF($I$3="Anual",SUMPRODUCT((Lancamentos!$A$2:$A$487="Despesa")*(Lancamentos!$B$2:$B$487<>"")*(YEAR(Lancamentos!$B$2:$B$487)=$B$3)*Lancamentos!$G$2:$G$487),D12))),0) | J5: 💰 SALDO | K5: =B5-G5 | M5: Luz | N5: 0
M6: Internet | N6: 0
A7: RESUMO DO MÊS | F7: GASTOS POR CATEGORIA | J7: INDICADORES | M7: Estacionamento | N7: 0
B8: Ciclo 1 | C8: Ciclo 2 | D8: Total | F8: Luz | G8: =IFERROR(SUMPRODUCT((Lancamentos!$A$2:$A$487="Despesa")*(Lancamentos!$B$2:$B$487<>"")*(MONTH(Lancamentos!$B$2:$B$487)=$B$2)*(YEAR(Lancamentos!$B$2:$B$487)=$B$3)*(Lancamentos!$D$2:$D$487="Luz")*Lancamentos!$G$2:$G$487),0) | H8: =IFERROR(G8/SUM(G$8:G$15),0) | J8: ⏳ Pendente | K8: =IFERROR(SUMPRODUCT((Lancamentos!$A$2:$A$487="Despesa")*(Lancamentos!$B$2:$B$487<>"")*(MONTH(Lancamentos!$B$2:$B$487)=$B$2)*(YEAR(Lancamentos!$B$2:$B$487)=$B$3)*(Lancamentos!$H$2:$H$487="Pendente")*Lancamentos!$G$2:$G$487),0) | M8: Cartão Will | N8: 0
A9: Will | B9: =IFERROR(SUMPRODUCT((Lancamentos!$A$2:$A$487="Receita")*(Lancamentos!$B$2:$B$487<>"")*(MONTH(Lancamentos!$B$2:$B$487)=$B$2)*(YEAR(Lancamentos!$B$2:$B$487)=$B$3)*(Lancamentos!$E$2:$E$487="Will")*(Lancamentos!$F$2:$F$487=1)*Lancamentos!$G$2:$G$487),0) | C9: =IFERROR(SUMPRODUCT((Lancamentos!$A$2:$A$487="Receita")*(Lancamentos!$B$2:$B$487<>"")*(MONTH(Lancamentos!$B$2:$B$487)=$B$2)*(YEAR(Lancamentos!$B$2:$B$487)=$B$3)*(Lancamentos!$E$2:$E$487="Will")*(Lancamentos!$F$2:$F$487=2)*Lancamentos!$G$2:$G$487),0) | D9: =SUM(B9:C9) | F9: Internet | G9: =IFERROR(SUMPRODUCT((Lancamentos!$A$2:$A$487="Despesa")*(Lancamentos!$B$2:$B$487<>"")*(MONTH(Lancamentos!$B$2:$B$487)=$B$2)*(YEAR(Lancamentos!$B$2:$B$487)=$B$3)*(Lancamentos!$D$2:$D$487="Internet")*Lancamentos!$G$2:$G$487),0) | H9: =IFERROR(G9/SUM(G$8:G$15),0) | J9: ✅ Pago | K9: =IFERROR(SUMPRODUCT((Lancamentos!$A$2:$A$487="Despesa")*(Lancamentos!$B$2:$B$487<>"")*(MONTH(Lancamentos!$B$2:$B$487)=$B$2)*(YEAR(Lancamentos!$B$2:$B$487)=$B$3)*(Lancamentos!$H$2:$H$487="Pago")*Lancamentos!$G$2:$G$487),0) | M9: Cartão Sá | N9: 0
A10: Sá | B10: =IFERROR(SUMPRODUCT((Lancamentos!$A$2:$A$487="Receita")*(Lancamentos!$B$2:$B$487<>"")*(MONTH(Lancamentos!$B$2:$B$487)=$B$2)*(YEAR(Lancamentos!$B$2:$B$487)=$B$3)*(Lancamentos!$E$2:$E$487="Sá")*(Lancamentos!$F$2:$F$487=1)*Lancamentos!$G$2:$G$487),0) | C10: =IFERROR(SUMPRODUCT((Lancamentos!$A$2:$A$487="Receita")*(Lancamentos!$B$2:$B$487<>"")*(MONTH(Lancamentos!$B$2:$B$487)=$B$2)*(YEAR(Lancamentos!$B$2:$B$487)=$B$3)*(Lancamentos!$E$2:$E$487="Sá")*(Lancamentos!$F$2:$F$487=2)*Lancamentos!$G$2:$G$487),0) | D10: =SUM(B10:C10) | F10: Aluguel | G10: =IFERROR(SUMPRODUCT((Lancamentos!$A$2:$A$487="Despesa")*(Lancamentos!$B$2:$B$487<>"")*(MONTH(Lancamentos!$B$2:$B$487)=$B$2)*(YEAR(Lancamentos!$B$2:$B$487)=$B$3)*(Lancamentos!$D$2:$D$487="Aluguel")*Lancamentos!$G$2:$G$487),0) | H10: =IFERROR(G10/SUM(G$8:G$15),0) | J10: 🔴 A Pagar | K10: =IFERROR(SUMPRODUCT((Lancamentos!$A$2:$A$487="Despesa")*(Lancamentos!$B$2:$B$487<>"")*(MONTH(Lancamentos!$B$2:$B$487)=$B$2)*(YEAR(Lancamentos!$B$2:$B$487)=$B$3)*(Lancamentos!$H$2:$H$487="A Pagar")*Lancamentos!$G$2:$G$487),0) | M10: Celular | N10: 0
A11: RECEITAS | B11: =SUM(B9:B10) | C11: =SUM(C9:C10) | D11: =SUM(D9:D10) | F11: Cartão Will | G11: =IFERROR(SUMPRODUCT((Lancamentos!$A$2:$A$487="Despesa")*(Lancamentos!$B$2:$B$487<>"")*(MONTH(Lancamentos!$B$2:$B$487)=$B$2)*(YEAR(Lancamentos!$B$2:$B$487)=$B$3)*(Lancamentos!$D$2:$D$487="Cartão Will")*Lancamentos!$G$2:$G$487),0) | H11: =IFERROR(G11/SUM(G$8:G$15),0) | M11: Areia | N11: 0
A12: DESPESAS | B12: =IFERROR(SUMPRODUCT((Lancamentos!$A$2:$A$487="Despesa")*(Lancamentos!$B$2:$B$487<>"")*(MONTH(Lancamentos!$B$2:$B$487)=$B$2)*(YEAR(Lancamentos!$B$2:$B$487)=$B$3)*(Lancamentos!$F$2:$F$487=1)*Lancamentos!$G$2:$G$487),0) | C12: =IFERROR(SUMPRODUCT((Lancamentos!$A$2:$A$487="Despesa")*(Lancamentos!$B$2:$B$487<>"")*(MONTH(Lancamentos!$B$2:$B$487)=$B$2)*(YEAR(Lancamentos!$B$2:$B$487)=$B$3)*(Lancamentos!$F$2:$F$487=2)*Lancamentos!$G$2:$G$487),0) | D12: =SUM(B12:C12) | F12: Alimentação | G12: =IFERROR(SUMPRODUCT((Lancamentos!$A$2:$A$487="Despesa")*(Lancamentos!$B$2:$B$487<>"")*(MONTH(Lancamentos!$B$2:$B$487)=$B$2)*(YEAR(Lancamentos!$B$2:$B$487)=$B$3)*(Lancamentos!$D$2:$D$487="Alimentação")*Lancamentos!$G$2:$G$487),0) | H12: =IFERROR(G12/SUM(G$8:G$15),0) | J12: % Comprometido | K12: =IFERROR(G5/B5,0) | M12: Unha mão | N12: 0
A13: SALDO | B13: =B11-B12 | C13: =C11-C12 | D13: =D11-D12 | F13: Condominio | G13: =IFERROR(SUMPRODUCT((Lancamentos!$A$2:$A$487="Despesa")*(Lancamentos!$B$2:$B$487<>"")*(MONTH(Lancamentos!$B$2:$B$487)=$B$2)*(YEAR(Lancamentos!$B$2:$B$487)=$B$3)*(Lancamentos!$D$2:$D$487="Condominio")*Lancamentos!$G$2:$G$487),0) | H13: =IFERROR(G13/SUM(G$8:G$15),0) | J13: Maior Gasto | K13: {=IFERROR(INDEX(F$8:F$15,MATCH(MAX(G$8:G$15),G$8:G$15,0)),"-")}
F14: Pets | G14: =IFERROR(SUMPRODUCT((Lancamentos!$A$2:$A$487="Despesa")*(Lancamentos!$B$2:$B$487<>"")*(MONTH(Lancamentos!$B$2:$B$487)=$B$2)*(YEAR(Lancamentos!$B$2:$B$487)=$B$3)*(Lancamentos!$D$2:$D$487="Pets")*Lancamentos!$G$2:$G$487),0) | H14: =IFERROR(G14/SUM(G$8:G$15),0) | J14: Nº Lançamentos | K14: =SUMPRODUCT((Lancamentos!$B$2:$B$487<>"")*(MONTH(Lancamentos!$B$2:$B$487)=$B$2)*(YEAR(Lancamentos!$B$2:$B$487)=$B$3))
F15: Combustivel | G15: =IFERROR(SUMPRODUCT((Lancamentos!$A$2:$A$487="Despesa")*(Lancamentos!$B$2:$B$487<>"")*(MONTH(Lancamentos!$B$2:$B$487)=$B$2)*(YEAR(Lancamentos!$B$2:$B$487)=$B$3)*(Lancamentos!$D$2:$D$487="Combustivel")*Lancamentos!$G$2:$G$487),0) | H15: =IFERROR(G15/SUM(G$8:G$15),0) | J15: Situação | K15: =IF(IFERROR(G5/B5,0)>0.8,"⚠️ Atenção",IF(IFERROR(G5/B5,0)>0.5,"⚡ Moderado","✅ Tranquilo"))
A17: PENDENTE | F17: PAGO / RECEBIDO | J17: A PAGAR
A19: 💡 Para lançar: menu 💰 Controle → 📝 Novo Lançamento
A20: 📈 CARTEIRA FIIs
A21: Total Investido | B21: 9.76
A22: Valor Atual | B22: 9.76
A23: Rentabilidade | B23: 0
A24: Div. Mês (estimado) | B24: 0.099999999
A25: Qtd de FIIs | B25: 1
A26: Melhor FII | B26: MXRF11 (73)

Sheet Lancamentos
A1: Tipo | B1: Data | C1: Descrição | D1: Categoria | E1: Responsável | F1: Ciclo | G1: Valor (R$) | H1: Status
A2: Receita | B2: 46204 | C2: Salário | D2: Salário | E2: Sá | F2: 1 | G2: 2000 | H2: Recebido
A3: Receita | B3: 46206.625 | C3: 13° Salário - Jun | D3: 13° Salário - Jun | E3: Will | F3: 1 | G3: 1687.8 | H3: Recebido
A4: Receita | B4: 46206.625 | C4: Salário | D4: Salário | E4: Will | F4: 1 | G4: 966.37 | H4: Recebido
A5: Despesa | B5: 46205.625 | C5: Luz | D5: Luz | E5: Ambos | F5: 1 | G5: 164.62 | H5: Pago
A6: Despesa | B6: 46205.625 | C6: Cartão Will | D6: Cartão Will | E6: Will | F6: 1 | G6: 250 | H6: Pago
A7: Despesa | B7: 46206.625 | C7: Ração | D7: Pets | E7: Ambos | F7: 1 | G7: 189.9 | H7: Pago
A8: Despesa | B8: 46206.625 | C8: Alimentação | D8: Alimentação | E8: Will | F8: 1 | G8: 24 | H8: Pago
A9: Despesa | B9: 46206.625 | C9: Transporte | D9: Transporte | E9: Will | F9: 1 | G9: 100 | H9: Pago
A10: Receita | B10: 46207.625 | C10: Outros | D10: Outros | E10: Will | F10: 1 | G10: 190 | H10: Recebido
A11: Despesa | B11: 46207.625 | C11: Ração | D11: Pets | E11: Ambos | F11: 1 | G11: 49.17 | H11: Pago
A12: Despesa | B12: 46207.625 | C12: Sem Parar - TAG | D12: Sem Parar - TAG | E12: Ambos | F12: 1 | G12: 129.7 | H12: Pago
A13: Receita | B13: 46207.625 | C13: Outros | D13: Outros | E13: Ambos | F13: 1 | G13: 3.18 | H13: Recebido
... A23: Despesa | B23: 46218.625 | C23: Pets | D23: Pets | E23: Ambos | F23: 2 | G23: 130 | H23: A Pagar

Sheet Investimentos
A1: Ticker | B1: Nome | C1: Segmento | D1: Qtd Cotas | E1: Preço Médio (R$) | F1: Valor Investido | G1: Preço Atual | H1: Valor Atual | I1: Lucro / Prej. | J1: Rentab. (%) | K1: DY 12m (%) | L1: P/VPA | M1: Var. Mês (%) | N1: Nota | O1: Análise | P1: Atualizado em | Q1: Div/Cota Mês (R$)

Sheet Cartoes
A1: Cartão | B1: Mês/Ano | C1: Valor Fatura (R$) | D1: Vencimento | E1: Status

Sheet Config
A1: Categorias | C1: Responsáveis | E1: Status | G1: Ciclo | I1: Nº | J1: Mês
A2: Salário | C2: Will | E2: Pendente | G2: 1 | I2: 1 | J2: Janeiro
A3: 13° Salário - Dez | C3: Sá | E3: Pago | G3: 2 | I3: 2 | J3: Fevereiro
A4: PLR | C4: Ambos | E4: A Pagar | I4: 3 | J4: Março
A5: Férias | E5: Recebido | I5: 4 | J5: Abril
A6: Renda Extra | I6: 5 | J6: Maio
A7: Luz | I7: 6 | J7: Junho
A8: Internet | I8: 7 | J8: Julho
A9: Condominio | I9: 8 | J9: Agosto
A10: Cartão Will | I10: 9 | J10: Setembro
A11: Cartão Sá | I11: 10 | J11: Outubro
A12: Gás | I12: 11 | J12: Novembro
A13: Pets | I13: 12 | J13: Dezembro
A14: Unha mão
A15: Mercado
A16: Aluguel
A17: Farmácia
A18: Transporte
A19: Lazer
A20: Alimentação
A21: Outros
A22: 13° Salário - Jun
A23: Adiantamento
A26: Sem Parar - TAG
A27: Combustível

Sheet Planejamento Viagem
B1: ✈️ PLANEJAMENTO DE VIAGEM
B3: 📋 DADOS DA VIAGEM
B4: Nome da Viagem | D4: Ex: Viagem a Floripa
B5: 🗺️ Cidade de Destino | H5: ← Ex: Florianópolis, SC
B6: Data de Saída | D6: ← preencha a data de saída
B7: Data de Retorno | D7: =IF(AND(C5<>"",C6<>""),TEXT(C6-C5,"0")&" dias","— informe as datas")
B8: Nº de Pessoas | C8: 2
B9: Orçamento Total (R$) | C9: 0
B11: ⛽ CALCULADORA DE COMBUSTÍVEL
B12: Distância total (km) | C12: 0 | E12: Ida + volta. Ex: SP→Floripa = 600km × 2
B13: Consumo do carro (km/L) | C13: 12 | E13: Consulte o manual do veículo
B14: Tipo de combustível | C14: Gasolina | E14: Gasolina / Etanol / Diesel
B15: Preço do combustível (R$/L) | C15: 5.5 | E15: ← insira o preço atual (veja nota abaixo)
B16: — Litros necessários | C16: =IFERROR(C11/C12,0) | E16: =distância ÷ consumo
B17: — Custo total combustível | C17: =IFERROR(C15*C14,0) | E17: =litros × preço
B18: — Custo por pessoa | C18: =IFERROR(C16/C7,0) | E18: =custo total ÷ nº pessoas (C7)
B19: 💡 Preço do combustível: consulte https://www.gov.br/anp (média semanal por estado) ou apps como Waze / Meu Combustível / Postos da Cidade.
B21: 🏨 HOSPEDAGEM
B22: Local / Acomodação | C22: Entrada | D22: Saída | E22: Noites | F22: R$/Noite | G22: Total
E23: =IFERROR(D22-C22,0) | G23: =IFERROR(E22*F22,0)
E24: =IFERROR(D23-C23,0) | G24: =IFERROR(E23*F23,0)
E25: =IFERROR(D24-C24,0) | G25: =IFERROR(E24*F24,0)
E26: =IFERROR(D25-C25,0) | G26: =IFERROR(E25*F25,0)
E27: =IFERROR(D26-C26,0) | G27: =IFERROR(E26*F26,0)
B28: TOTAL HOSPEDAGEM | G28: =SUM(G22:G26)
B30: 🍽️ ALIMENTAÇÃO
B31: Custo estimado por pessoa/dia (R$) | C31: 80
B32: Número de dias | C32: =IFERROR(C6-C5,0)
B33: Número de pessoas | C33: =C7
B34: — TOTAL ALIMENTAÇÃO | C34: =IFERROR(C30*C31*C32,0)
B36: 🎡 PASSEIOS E OUTROS
B37: Descrição | C37: Tipo | G37: Valor (R$)
B44: TOTAL OUTROS | G44: =SUM(G37:G42)
B46: 💰 RESUMO TOTAL DA VIAGEM
B47: ⛽ Combustível | G47: =C16
B48: 🏨 Hospedagem | G48: =G27
B49: 🍽️ Alimentação | G49: =C33
B50: 🎡 Outros | G50: =G43
B51: 🧳 TOTAL DA VIAGEM | G51: =SUM(G46:G49)
B52: 👤 Total por pessoa | G52: =IFERROR(G50/C7,0)
...

Sheet Compras & Metas
A1: 🛒 COMPRAS & METAS FINANCEIRAS
A3: 🎯 CALCULADORA DE META — Quanto guardar por mês
A4: Produto / Objetivo
A5: Valor total necessário (R$) | E5: 0
A6: Já tenho guardado (R$) | E6: 0
A7: → Quanto ainda falta (R$) | E7: =IFERROR(E5-E6,0)
A9: 📌 OPÇÃO A — Quero comprar em X meses | E9: 📌 OPÇÃO B — Consigo guardar X por mês
A10: Quero comprar em (meses): | C10: 12 | E10: Consigo guardar por mês (R$): | G10: 500
A11: → Guardar por mês: | C11: =IFERROR(E7/C10,0) | E11: → Meses até a compra: | G11: =IFERROR(CEILING(E7/G10,1),0)
A12: → Data estimada (Opção A): | C12: =IFERROR(EDATE(TODAY(),C10),"") | E12: → Data estimada (Opção B): | G12: =IFERROR(EDATE(TODAY(),G11),"")
A14: 📋 LISTA DE METAS DE COMPRA
A15: # | B15: Produto | C15: Valor (R$) | D15: Guardado (R$) | E15: Falta (R$) | F15: Poupar/mês | G15: Meses | H15: Previsão
A16: 1 | E16: =IFERROR(C16-D16,0) | F16: =IFERROR(E16/C10,0) | G16: =IFERROR(CEILING(E16/G10,1),0) | H16: =IFERROR(EDATE(TODAY(),G16),"")
A17: 2 | E17: =IFERROR(C17-D17,0) | F17: =IFERROR(E17/C10,0) | G17: =IFERROR(CEILING(E17/G10,1),0) | H17: =IFERROR(EDATE(TODAY(),G17),"")
A18: 3 | E18: =IFERROR(C18-D18,0) | F18: =IFERROR(E18/C10,0) | G18: =IFERROR(CEILING(E18/G10,1),0) | H18: =IFERROR(EDATE(TODAY(),G18),"")
A19: 4 | E19: =IFERROR(C19-D19,0) | F19: =IFERROR(E19/C10,0) | G19: =IFERROR(CEILING(E19/G10,1),0) | H19: =IFERROR(EDATE(TODAY(),G19),"")
A20: 5 | E20: =IFERROR(C20-D20,0) | F20: =IFERROR(E20/C10,0) | G20: =IFERROR(CEILING(E20/G10,1),0) | H20: =IFERROR(EDATE(TODAY(),G20),"")
A21: 6 | E21: =IFERROR(C21-D21,0) | F21: =IFERROR(E21/C10,0) | G21: =IFERROR(CEILING(E21/G10,1),0) | H21: =IFERROR(EDATE(TODAY(),G21),"")
A24: 💳 CALCULADORA: À VISTA vs PARCELADO
A25: Preencha os campos em AZUL — o restante é calculado automaticamente
A26: Produto / Descrição
A27: Preço à VISTA (R$) | E27: 0
A28: Desconto à vista (%) | E28: 0
A29: → Preço à vista c/ desconto | E29: =IFERROR(E27*(1-E28/100),E27)
A30: Número de parcelas | E30: 12
A31: Valor de cada parcela (R$) | E31: 0
A33: 📊 ANÁLISE COMPARATIVA
A34: 💵 Total pago à vista | E34: =IFERROR(E29,E27)
A35: 💳 Total pago parcelado | E35: =IFERROR(E30*E31,0)
A36: 📈 Quanto a mais no parcelado (R$) | E36: =IFERROR(E35-E34,0)
A37: 📈 Quanto a mais no parcelado (%) | E37: =IFERROR((E35/E34-1)*100,0)
A38: 🔢 Taxa de juros mensal (RATE) | E38: =IFERROR(RATE(E30,-E31,E29)*100,0)
A39: 🔢 Taxa de juros anual equivalente | E39: =IFERROR(((1+E38/100)^12-1)*100,0)
A41: =IFERROR(IF(E38<=0,"⚠️ Preencha preço à vista e valor da parcela", IF(E38<0.8,"✅ JUROS BAIXOS ("&TEXT(E38,"0.00")&"% a.m.) — Parcelar pode valer se você investir a diferença", IF(E38<1.5,"⚡ JUROS MODERADOS ("&TEXT(E38,"0.00")&"% a.m.) — Prefira à vista se possível", IF(E38<3,"🔴 JUROS ALTOS ("&TEXT(E38,"0.00")&"% a.m.) — Compre À VISTA. Parcelado custa "&TEXT(E36,"R$ #,##0.00")&" a mais", "🚨 JUROS ABUSIVOS ("&TEXT(E38,"0.00")&"% a.m.) — NUNCA parcele nessas condições!")))),"Preencha os dados")
A42: 💡 Dica: Se os juros forem menores que o rendimento da sua reserva (ex: CDB/Tesouro ~0,8%/mês), pode valer guardar o dinheiro e parcelar. Mas se não tiver disciplina, pague à vista.
